2018-08-05 13:00:26,319 [base:get_response] [WARNING]- Not Found: /
2018-08-05 13:00:26,438 [base:get_response] [WARNING]- Not Found: /favicon.ico
2018-08-05 13:08:23,535 [base:get_response] [WARNING]- Not Found: /
2018-08-05 13:11:43,084 [base:get_response] [WARNING]- Not Found: /
2018-08-05 13:14:21,233 [base:get_response] [WARNING]- Not Found: /
2018-08-07 22:32:42,055 [base:get_response] [WARNING]- Not Found: /
2018-08-07 22:32:42,207 [base:get_response] [WARNING]- Not Found: /favicon.ico
2018-08-08 00:05:07,108 [base:get_response] [WARNING]- Not Found: /editVipPerson/
2018-08-08 00:18:51,369 [exception:handle_uncaught_exception] [ERROR]- Internal Server Error: /editVipPerson/
Traceback (most recent call last):
  File "C:\Python27\lib\site-packages\django\core\handlers\exception.py", line 41, in inner
    response = get_response(request)
  File "C:\Python27\lib\site-packages\django\core\handlers\base.py", line 187, in _get_response
    response = self.process_exception_by_middleware(e, request)
  File "C:\Python27\lib\site-packages\django\core\handlers\base.py", line 185, in _get_response
    response = wrapped_callback(request, *callback_args, **callback_kwargs)
  File "D:\Study\VMS\vipMangementSystem\vms\views.py", line 146, in edit_vip_person
    is_exist = db.getAll("SELECT * from person where phone ='%s' AND id NOT IN('%s')" % (data['phone']),data['id'])
TypeError: not enough arguments for format string
2018-08-08 00:19:18,714 [exception:handle_uncaught_exception] [ERROR]- Internal Server Error: /editVipPerson/
Traceback (most recent call last):
  File "C:\Python27\lib\site-packages\django\core\handlers\exception.py", line 41, in inner
    response = get_response(request)
  File "C:\Python27\lib\site-packages\django\core\handlers\base.py", line 187, in _get_response
    response = self.process_exception_by_middleware(e, request)
  File "C:\Python27\lib\site-packages\django\core\handlers\base.py", line 185, in _get_response
    response = wrapped_callback(request, *callback_args, **callback_kwargs)
  File "D:\Study\VMS\vipMangementSystem\vms\views.py", line 146, in edit_vip_person
    is_exist = db.getAll("SELECT * from person where phone ='%s' AND id NOT IN('%s')" % (data['phone']),data['id'])
TypeError: not enough arguments for format string
2018-08-08 00:19:35,259 [exception:handle_uncaught_exception] [ERROR]- Internal Server Error: /editVipPerson/
Traceback (most recent call last):
  File "C:\Python27\lib\site-packages\django\core\handlers\exception.py", line 41, in inner
    response = get_response(request)
  File "C:\Python27\lib\site-packages\django\core\handlers\base.py", line 187, in _get_response
    response = self.process_exception_by_middleware(e, request)
  File "C:\Python27\lib\site-packages\django\core\handlers\base.py", line 185, in _get_response
    response = wrapped_callback(request, *callback_args, **callback_kwargs)
  File "D:\Study\VMS\vipMangementSystem\vms\views.py", line 146, in edit_vip_person
    is_exist = db.getAll("SELECT * from person where phone ='%s' AND id NOT IN('%s')" % (data['phone']),data['id'])
TypeError: not enough arguments for format string
2018-08-08 00:20:26,084 [exception:handle_uncaught_exception] [ERROR]- Internal Server Error: /editVipPerson/
Traceback (most recent call last):
  File "C:\Python27\lib\site-packages\django\core\handlers\exception.py", line 41, in inner
    response = get_response(request)
  File "C:\Python27\lib\site-packages\django\core\handlers\base.py", line 187, in _get_response
    response = self.process_exception_by_middleware(e, request)
  File "C:\Python27\lib\site-packages\django\core\handlers\base.py", line 185, in _get_response
    response = wrapped_callback(request, *callback_args, **callback_kwargs)
  File "D:\Study\VMS\vipMangementSystem\vms\views.py", line 146, in edit_vip_person
    is_exist = db.getAll("SELECT * from person where phone ='%s' AND id NOT IN('%s')" % (data['phone']),data['id'])
TypeError: not enough arguments for format string
2018-08-08 00:20:36,397 [exception:handle_uncaught_exception] [ERROR]- Internal Server Error: /editVipPerson/
Traceback (most recent call last):
  File "C:\Python27\lib\site-packages\django\core\handlers\exception.py", line 41, in inner
    response = get_response(request)
  File "C:\Python27\lib\site-packages\django\core\handlers\base.py", line 187, in _get_response
    response = self.process_exception_by_middleware(e, request)
  File "C:\Python27\lib\site-packages\django\core\handlers\base.py", line 185, in _get_response
    response = wrapped_callback(request, *callback_args, **callback_kwargs)
  File "D:\Study\VMS\vipMangementSystem\vms\views.py", line 146, in edit_vip_person
    is_exist = db.getAll("SELECT * from person where phone ='%s' AND id NOT IN('%s')" % (data['phone']),data['id'])
TypeError: not enough arguments for format string
2018-08-08 00:20:40,345 [exception:handle_uncaught_exception] [ERROR]- Internal Server Error: /editVipPerson/
Traceback (most recent call last):
  File "C:\Python27\lib\site-packages\django\core\handlers\exception.py", line 41, in inner
    response = get_response(request)
  File "C:\Python27\lib\site-packages\django\core\handlers\base.py", line 187, in _get_response
    response = self.process_exception_by_middleware(e, request)
  File "C:\Python27\lib\site-packages\django\core\handlers\base.py", line 185, in _get_response
    response = wrapped_callback(request, *callback_args, **callback_kwargs)
  File "D:\Study\VMS\vipMangementSystem\vms\views.py", line 146, in edit_vip_person
    is_exist = db.getAll("SELECT * from person where phone ='%s' AND id NOT IN('%s')" % (data['phone']),data['id'])
TypeError: not enough arguments for format string
2018-08-08 00:21:31,575 [exception:handle_uncaught_exception] [ERROR]- Internal Server Error: /editVipPerson/
Traceback (most recent call last):
  File "C:\Python27\lib\site-packages\django\core\handlers\exception.py", line 41, in inner
    response = get_response(request)
  File "C:\Python27\lib\site-packages\django\core\handlers\base.py", line 187, in _get_response
    response = self.process_exception_by_middleware(e, request)
  File "C:\Python27\lib\site-packages\django\core\handlers\base.py", line 185, in _get_response
    response = wrapped_callback(request, *callback_args, **callback_kwargs)
  File "D:\Study\VMS\vipMangementSystem\vms\views.py", line 147, in edit_vip_person
    is_exist = db.getAll("SELECT * from person where phone ='%s' AND id NOT IN('%s')" % (data['phone']),data['id'])
TypeError: not enough arguments for format string
2018-08-08 00:28:11,561 [exception:handle_uncaught_exception] [ERROR]- Internal Server Error: /editVipPerson/
Traceback (most recent call last):
  File "C:\Python27\lib\site-packages\django\core\handlers\exception.py", line 41, in inner
    response = get_response(request)
  File "C:\Python27\lib\site-packages\django\core\handlers\base.py", line 187, in _get_response
    response = self.process_exception_by_middleware(e, request)
  File "C:\Python27\lib\site-packages\django\core\handlers\base.py", line 185, in _get_response
    response = wrapped_callback(request, *callback_args, **callback_kwargs)
  File "D:\Study\VMS\vipMangementSystem\vms\views.py", line 146, in edit_vip_person
    sql2 ="SELECT * from person where phone ='%s' AND id NOT IN('%s')"%(data['phone'],data['id'])
  File "C:\Python27\lib\site-packages\django\utils\datastructures.py", line 85, in __getitem__
    raise MultiValueDictKeyError(repr(key))
MultiValueDictKeyError: "u'id'"
2018-08-08 00:29:25,861 [base:get_response] [WARNING]- Not Found: /
2018-08-08 00:29:32,877 [exception:handle_uncaught_exception] [ERROR]- Internal Server Error: /editVipPerson/
Traceback (most recent call last):
  File "C:\Python27\lib\site-packages\django\core\handlers\exception.py", line 41, in inner
    response = get_response(request)
  File "C:\Python27\lib\site-packages\django\core\handlers\base.py", line 187, in _get_response
    response = self.process_exception_by_middleware(e, request)
  File "C:\Python27\lib\site-packages\django\core\handlers\base.py", line 185, in _get_response
    response = wrapped_callback(request, *callback_args, **callback_kwargs)
  File "D:\Study\VMS\vipMangementSystem\vms\views.py", line 145, in edit_vip_person
    sql2 = "SELECT * from person where phone ='%s' AND id NOT IN('%s')" %(data['phone'],data['id'])
  File "C:\Python27\lib\site-packages\django\utils\datastructures.py", line 85, in __getitem__
    raise MultiValueDictKeyError(repr(key))
MultiValueDictKeyError: "u'id'"
2018-08-08 00:30:02,224 [exception:handle_uncaught_exception] [ERROR]- Internal Server Error: /editVipPerson/
Traceback (most recent call last):
  File "C:\Python27\lib\site-packages\django\core\handlers\exception.py", line 41, in inner
    response = get_response(request)
  File "C:\Python27\lib\site-packages\django\core\handlers\base.py", line 187, in _get_response
    response = self.process_exception_by_middleware(e, request)
  File "C:\Python27\lib\site-packages\django\core\handlers\base.py", line 185, in _get_response
    response = wrapped_callback(request, *callback_args, **callback_kwargs)
  File "D:\Study\VMS\vipMangementSystem\vms\views.py", line 146, in edit_vip_person
    sql2 = "SELECT * from person where phone ='%s' AND id NOT IN('%s')" %(data['phone'],data['id'])
  File "C:\Python27\lib\site-packages\django\utils\datastructures.py", line 85, in __getitem__
    raise MultiValueDictKeyError(repr(key))
MultiValueDictKeyError: "u'id'"
2018-08-08 00:30:31,648 [exception:handle_uncaught_exception] [ERROR]- Internal Server Error: /editVipPerson/
Traceback (most recent call last):
  File "C:\Python27\lib\site-packages\django\core\handlers\exception.py", line 41, in inner
    response = get_response(request)
  File "C:\Python27\lib\site-packages\django\core\handlers\base.py", line 187, in _get_response
    response = self.process_exception_by_middleware(e, request)
  File "C:\Python27\lib\site-packages\django\core\handlers\base.py", line 185, in _get_response
    response = wrapped_callback(request, *callback_args, **callback_kwargs)
  File "D:\Study\VMS\vipMangementSystem\vms\views.py", line 147, in edit_vip_person
    sql2 = "SELECT * from person where phone ='%s' AND id NOT IN('%s')" %(data['phone'],data['id'])
  File "C:\Python27\lib\site-packages\django\utils\datastructures.py", line 85, in __getitem__
    raise MultiValueDictKeyError(repr(key))
MultiValueDictKeyError: "u'id'"
2018-08-08 00:30:45,569 [exception:handle_uncaught_exception] [ERROR]- Internal Server Error: /editVipPerson/
Traceback (most recent call last):
  File "C:\Python27\lib\site-packages\django\core\handlers\exception.py", line 41, in inner
    response = get_response(request)
  File "C:\Python27\lib\site-packages\django\core\handlers\base.py", line 187, in _get_response
    response = self.process_exception_by_middleware(e, request)
  File "C:\Python27\lib\site-packages\django\core\handlers\base.py", line 185, in _get_response
    response = wrapped_callback(request, *callback_args, **callback_kwargs)
  File "D:\Study\VMS\vipMangementSystem\vms\views.py", line 148, in edit_vip_person
    sql2 = "SELECT * from person where phone ='%s' AND id NOT IN('%s')" %(data['phone'],data['id'])
  File "C:\Python27\lib\site-packages\django\utils\datastructures.py", line 85, in __getitem__
    raise MultiValueDictKeyError(repr(key))
MultiValueDictKeyError: "u'id'"
2018-08-08 00:31:32,385 [exception:handle_uncaught_exception] [ERROR]- Internal Server Error: /editVipPerson/
Traceback (most recent call last):
  File "C:\Python27\lib\site-packages\django\core\handlers\exception.py", line 41, in inner
    response = get_response(request)
  File "C:\Python27\lib\site-packages\django\core\handlers\base.py", line 187, in _get_response
    response = self.process_exception_by_middleware(e, request)
  File "C:\Python27\lib\site-packages\django\core\handlers\base.py", line 185, in _get_response
    response = wrapped_callback(request, *callback_args, **callback_kwargs)
  File "D:\Study\VMS\vipMangementSystem\vms\views.py", line 147, in edit_vip_person
    sql2 = "SELECT * from person where phone =\'%s\' AND id NOT IN(%s)" %(data['phone'],data['id'])
  File "C:\Python27\lib\site-packages\django\utils\datastructures.py", line 85, in __getitem__
    raise MultiValueDictKeyError(repr(key))
MultiValueDictKeyError: "u'id'"
2018-08-08 00:33:02,642 [exception:handle_uncaught_exception] [ERROR]- Internal Server Error: /editVipPerson/
Traceback (most recent call last):
  File "C:\Python27\lib\site-packages\django\core\handlers\exception.py", line 41, in inner
    response = get_response(request)
  File "C:\Python27\lib\site-packages\django\core\handlers\base.py", line 187, in _get_response
    response = self.process_exception_by_middleware(e, request)
  File "C:\Python27\lib\site-packages\django\core\handlers\base.py", line 185, in _get_response
    response = wrapped_callback(request, *callback_args, **callback_kwargs)
  File "D:\Study\VMS\vipMangementSystem\vms\views.py", line 147, in edit_vip_person
    sql2 = "SELECT * from person where phone =\'%s\' and id not in (\'%s\') " %(data['phone'],data['id'])
  File "C:\Python27\lib\site-packages\django\utils\datastructures.py", line 85, in __getitem__
    raise MultiValueDictKeyError(repr(key))
MultiValueDictKeyError: "u'id'"
2018-08-08 00:34:18,473 [exception:handle_uncaught_exception] [ERROR]- Internal Server Error: /editVipPerson/
Traceback (most recent call last):
  File "C:\Python27\lib\site-packages\django\core\handlers\exception.py", line 41, in inner
    response = get_response(request)
  File "C:\Python27\lib\site-packages\django\core\handlers\base.py", line 187, in _get_response
    response = self.process_exception_by_middleware(e, request)
  File "C:\Python27\lib\site-packages\django\core\handlers\base.py", line 185, in _get_response
    response = wrapped_callback(request, *callback_args, **callback_kwargs)
  File "D:\Study\VMS\vipMangementSystem\vms\views.py", line 147, in edit_vip_person
    sql2 = "SELECT * from person where phone =\'%s\' and id not in (\'%s\') " %(data['phone'],data['id'])
  File "C:\Python27\lib\site-packages\django\utils\datastructures.py", line 85, in __getitem__
    raise MultiValueDictKeyError(repr(key))
MultiValueDictKeyError: "u'id'"
2018-08-08 00:35:29,463 [exception:handle_uncaught_exception] [ERROR]- Internal Server Error: /editVipPerson/
Traceback (most recent call last):
  File "C:\Python27\lib\site-packages\django\core\handlers\exception.py", line 41, in inner
    response = get_response(request)
  File "C:\Python27\lib\site-packages\django\core\handlers\base.py", line 187, in _get_response
    response = self.process_exception_by_middleware(e, request)
  File "C:\Python27\lib\site-packages\django\core\handlers\base.py", line 185, in _get_response
    response = wrapped_callback(request, *callback_args, **callback_kwargs)
  File "D:\Study\VMS\vipMangementSystem\vms\views.py", line 147, in edit_vip_person
    sql2 = "SELECT * from person where phone =\'%s\' and id != \'%s\' " %(data['phone'],data['id'])
  File "C:\Python27\lib\site-packages\django\utils\datastructures.py", line 85, in __getitem__
    raise MultiValueDictKeyError(repr(key))
MultiValueDictKeyError: "u'id'"
2018-08-08 00:37:01,029 [exception:handle_uncaught_exception] [ERROR]- Internal Server Error: /editVipPerson/
Traceback (most recent call last):
  File "C:\Python27\lib\site-packages\django\core\handlers\exception.py", line 41, in inner
    response = get_response(request)
  File "C:\Python27\lib\site-packages\django\core\handlers\base.py", line 187, in _get_response
    response = self.process_exception_by_middleware(e, request)
  File "C:\Python27\lib\site-packages\django\core\handlers\base.py", line 185, in _get_response
    response = wrapped_callback(request, *callback_args, **callback_kwargs)
  File "D:\Study\VMS\vipMangementSystem\vms\views.py", line 159, in edit_vip_person
    sql = "UPDATE person SET name = '%s',sex= '%s',phone='%s',note='%s',create_time = now() WHERE id=%s" % (data['username'], data['sex'], data['phone'], data['desc'],data['id'])
  File "C:\Python27\lib\site-packages\django\utils\datastructures.py", line 85, in __getitem__
    raise MultiValueDictKeyError(repr(key))
MultiValueDictKeyError: "u'id'"
2018-08-08 00:38:05,244 [exception:handle_uncaught_exception] [ERROR]- Internal Server Error: /editVipPerson/
Traceback (most recent call last):
  File "C:\Python27\lib\site-packages\django\core\handlers\exception.py", line 41, in inner
    response = get_response(request)
  File "C:\Python27\lib\site-packages\django\core\handlers\base.py", line 187, in _get_response
    response = self.process_exception_by_middleware(e, request)
  File "C:\Python27\lib\site-packages\django\core\handlers\base.py", line 185, in _get_response
    response = wrapped_callback(request, *callback_args, **callback_kwargs)
  File "D:\Study\VMS\vipMangementSystem\vms\views.py", line 147, in edit_vip_person
    sql2 = "SELECT * from person where phone ='%s'  and id != %d" %(data['phone'],data['id'])
  File "C:\Python27\lib\site-packages\django\utils\datastructures.py", line 85, in __getitem__
    raise MultiValueDictKeyError(repr(key))
MultiValueDictKeyError: "u'id'"
2018-08-08 00:38:43,040 [exception:handle_uncaught_exception] [ERROR]- Internal Server Error: /editVipPerson/
Traceback (most recent call last):
  File "C:\Python27\lib\site-packages\django\core\handlers\exception.py", line 41, in inner
    response = get_response(request)
  File "C:\Python27\lib\site-packages\django\core\handlers\base.py", line 187, in _get_response
    response = self.process_exception_by_middleware(e, request)
  File "C:\Python27\lib\site-packages\django\core\handlers\base.py", line 185, in _get_response
    response = wrapped_callback(request, *callback_args, **callback_kwargs)
  File "D:\Study\VMS\vipMangementSystem\vms\views.py", line 147, in edit_vip_person
    print (data['id'])
  File "C:\Python27\lib\site-packages\django\utils\datastructures.py", line 85, in __getitem__
    raise MultiValueDictKeyError(repr(key))
MultiValueDictKeyError: "u'id'"
2018-08-08 00:38:59,697 [exception:handle_uncaught_exception] [ERROR]- Internal Server Error: /editVipPerson/
Traceback (most recent call last):
  File "C:\Python27\lib\site-packages\django\core\handlers\exception.py", line 41, in inner
    response = get_response(request)
  File "C:\Python27\lib\site-packages\django\core\handlers\base.py", line 187, in _get_response
    response = self.process_exception_by_middleware(e, request)
  File "C:\Python27\lib\site-packages\django\core\handlers\base.py", line 185, in _get_response
    response = wrapped_callback(request, *callback_args, **callback_kwargs)
  File "D:\Study\VMS\vipMangementSystem\vms\views.py", line 141, in edit_vip_person
    print (data['id'])
  File "C:\Python27\lib\site-packages\django\utils\datastructures.py", line 85, in __getitem__
    raise MultiValueDictKeyError(repr(key))
MultiValueDictKeyError: "u'id'"
2018-08-08 00:40:17,420 [exception:handle_uncaught_exception] [ERROR]- Internal Server Error: /editVipPerson/
Traceback (most recent call last):
  File "C:\Python27\lib\site-packages\django\core\handlers\exception.py", line 41, in inner
    response = get_response(request)
  File "C:\Python27\lib\site-packages\django\core\handlers\base.py", line 187, in _get_response
    response = self.process_exception_by_middleware(e, request)
  File "C:\Python27\lib\site-packages\django\core\handlers\base.py", line 185, in _get_response
    response = wrapped_callback(request, *callback_args, **callback_kwargs)
  File "D:\Study\VMS\vipMangementSystem\vms\views.py", line 149, in edit_vip_person
    sql2 = "SELECT * from person where phone ='%s' and person.name != %d" %(data['phone'],data['username'])
TypeError: %d format: a number is required, not unicode
2018-08-08 00:41:11,849 [exception:handle_uncaught_exception] [ERROR]- Internal Server Error: /editVipPerson/
Traceback (most recent call last):
  File "C:\Python27\lib\site-packages\django\core\handlers\exception.py", line 41, in inner
    response = get_response(request)
  File "C:\Python27\lib\site-packages\django\core\handlers\base.py", line 187, in _get_response
    response = self.process_exception_by_middleware(e, request)
  File "C:\Python27\lib\site-packages\django\core\handlers\base.py", line 185, in _get_response
    response = wrapped_callback(request, *callback_args, **callback_kwargs)
  File "D:\Study\VMS\vipMangementSystem\vms\views.py", line 161, in edit_vip_person
    sql = "UPDATE person SET name = '%s',sex= '%s',phone='%s',note='%s',create_time = now() WHERE id=%s" % (data['username'], data['sex'], data['phone'], data['desc'],data['id'])
  File "C:\Python27\lib\site-packages\django\utils\datastructures.py", line 85, in __getitem__
    raise MultiValueDictKeyError(repr(key))
MultiValueDictKeyError: "u'id'"
2018-08-08 00:49:00,002 [exception:handle_uncaught_exception] [ERROR]- Internal Server Error: /editVipPerson/
Traceback (most recent call last):
  File "C:\Python27\lib\site-packages\django\core\handlers\exception.py", line 41, in inner
    response = get_response(request)
  File "C:\Python27\lib\site-packages\django\core\handlers\base.py", line 187, in _get_response
    response = self.process_exception_by_middleware(e, request)
  File "C:\Python27\lib\site-packages\django\core\handlers\base.py", line 185, in _get_response
    response = wrapped_callback(request, *callback_args, **callback_kwargs)
  File "D:\Study\VMS\vipMangementSystem\vms\views.py", line 161, in edit_vip_person
    sql = "UPDATE person SET name = '%s',sex= '%s',phone='%s',note='%s',create_time = now() WHERE id=%s" % (data['username'], data['sex'], data['phone'], data['desc'],data['id'])
  File "C:\Python27\lib\site-packages\django\utils\datastructures.py", line 85, in __getitem__
    raise MultiValueDictKeyError(repr(key))
MultiValueDictKeyError: "u'id'"
2018-08-08 22:46:12,059 [base:get_response] [WARNING]- Not Found: /
2018-08-08 22:46:12,536 [base:get_response] [WARNING]- Not Found: /favicon.ico
2018-08-09 00:06:37,500 [exception:handle_uncaught_exception] [ERROR]- Internal Server Error: /queryVipPerson/
Traceback (most recent call last):
  File "C:\Python27\lib\site-packages\django\core\handlers\exception.py", line 41, in inner
    response = get_response(request)
  File "C:\Python27\lib\site-packages\django\core\handlers\base.py", line 198, in _get_response
    "returned None instead." % (callback.__module__, view_name)
ValueError: The view vms.views.query_vip_person didn't return an HttpResponse object. It returned None instead.
2018-08-09 00:12:27,815 [exception:handle_uncaught_exception] [ERROR]- Internal Server Error: /queryVipPerson/
Traceback (most recent call last):
  File "C:\Python27\lib\site-packages\django\core\handlers\exception.py", line 41, in inner
    response = get_response(request)
  File "C:\Python27\lib\site-packages\django\core\handlers\base.py", line 187, in _get_response
    response = self.process_exception_by_middleware(e, request)
  File "C:\Python27\lib\site-packages\django\core\handlers\base.py", line 185, in _get_response
    response = wrapped_callback(request, *callback_args, **callback_kwargs)
  File "D:\Study\VMS\vipMangementSystem\vms\views.py", line 202, in query_vip_person
    query_result = db.getAll(sql)
  File "D:\Study\VMS\vipMangementSystem\vms\DB.py", line 239, in getAll
    count = self._cursor.execute(sql)
  File "C:\Python27\lib\site-packages\DBUtils\SteadyDB.py", line 580, in tough_method
    result = method(*args, **kwargs)  # try to execute
  File "C:\Python27\lib\site-packages\MySQLdb\cursors.py", line 174, in execute
    self.errorhandler(self, exc, value)
  File "C:\Python27\lib\site-packages\MySQLdb\connections.py", line 36, in defaulterrorhandler
    raise errorclass, errorvalue
ProgrammingError: (1064, "You have an error in your SQL syntax; check the manual that corresponds to your MySQL server version for the right syntax to use near 'a  LEFT JOIN point_detail b ON a.id = b.person_id  ORDER BY a.id desc' at line 1")
2018-08-09 00:19:25,994 [exception:handle_uncaught_exception] [ERROR]- Internal Server Error: /queryVipPerson/
Traceback (most recent call last):
  File "C:\Python27\lib\site-packages\django\core\handlers\exception.py", line 41, in inner
    response = get_response(request)
  File "C:\Python27\lib\site-packages\django\core\handlers\base.py", line 187, in _get_response
    response = self.process_exception_by_middleware(e, request)
  File "C:\Python27\lib\site-packages\django\core\handlers\base.py", line 185, in _get_response
    response = wrapped_callback(request, *callback_args, **callback_kwargs)
  File "D:\Study\VMS\vipMangementSystem\vms\views.py", line 211, in query_vip_person
    limit = int(req.GET['limit'])
  File "C:\Python27\lib\site-packages\django\utils\datastructures.py", line 85, in __getitem__
    raise MultiValueDictKeyError(repr(key))
MultiValueDictKeyError: "u'limit'"
2018-08-09 00:20:14,674 [exception:handle_uncaught_exception] [ERROR]- Internal Server Error: /queryVipPerson/
Traceback (most recent call last):
  File "C:\Python27\lib\site-packages\django\core\handlers\exception.py", line 41, in inner
    response = get_response(request)
  File "C:\Python27\lib\site-packages\django\core\handlers\base.py", line 187, in _get_response
    response = self.process_exception_by_middleware(e, request)
  File "C:\Python27\lib\site-packages\django\core\handlers\base.py", line 185, in _get_response
    response = wrapped_callback(request, *callback_args, **callback_kwargs)
  File "D:\Study\VMS\vipMangementSystem\vms\views.py", line 212, in query_vip_person
    limit = int(req.GET['limit'])
  File "C:\Python27\lib\site-packages\django\utils\datastructures.py", line 85, in __getitem__
    raise MultiValueDictKeyError(repr(key))
MultiValueDictKeyError: "u'limit'"
2018-08-09 00:20:47,605 [exception:handle_uncaught_exception] [ERROR]- Internal Server Error: /queryVipPerson/
Traceback (most recent call last):
  File "C:\Python27\lib\site-packages\django\core\handlers\exception.py", line 41, in inner
    response = get_response(request)
  File "C:\Python27\lib\site-packages\django\core\handlers\base.py", line 187, in _get_response
    response = self.process_exception_by_middleware(e, request)
  File "C:\Python27\lib\site-packages\django\core\handlers\base.py", line 185, in _get_response
    response = wrapped_callback(request, *callback_args, **callback_kwargs)
  File "D:\Study\VMS\vipMangementSystem\vms\views.py", line 212, in query_vip_person
    limit = int(req.GET['limit'])
  File "C:\Python27\lib\site-packages\django\utils\datastructures.py", line 85, in __getitem__
    raise MultiValueDictKeyError(repr(key))
MultiValueDictKeyError: "u'limit'"
2018-08-09 00:30:01,220 [exception:handle_uncaught_exception] [ERROR]- Internal Server Error: /queryVipPerson/
Traceback (most recent call last):
  File "C:\Python27\lib\site-packages\django\core\handlers\exception.py", line 41, in inner
    response = get_response(request)
  File "C:\Python27\lib\site-packages\django\core\handlers\base.py", line 187, in _get_response
    response = self.process_exception_by_middleware(e, request)
  File "C:\Python27\lib\site-packages\django\core\handlers\base.py", line 185, in _get_response
    response = wrapped_callback(request, *callback_args, **callback_kwargs)
  File "D:\Study\VMS\vipMangementSystem\vms\views.py", line 211, in query_vip_person
    limit = int(req.GET['limit'])
  File "C:\Python27\lib\site-packages\django\utils\datastructures.py", line 85, in __getitem__
    raise MultiValueDictKeyError(repr(key))
MultiValueDictKeyError: "u'limit'"
2018-08-09 00:33:17,815 [exception:handle_uncaught_exception] [ERROR]- Internal Server Error: /listVipPerson/
Traceback (most recent call last):
  File "C:\Python27\lib\site-packages\django\core\handlers\exception.py", line 41, in inner
    response = get_response(request)
  File "C:\Python27\lib\site-packages\django\core\handlers\base.py", line 187, in _get_response
    response = self.process_exception_by_middleware(e, request)
  File "C:\Python27\lib\site-packages\django\core\handlers\base.py", line 185, in _get_response
    response = wrapped_callback(request, *callback_args, **callback_kwargs)
  File "D:\Study\VMS\vipMangementSystem\vms\views.py", line 25, in list_vip_person
    sql2 = "SELECT a.id, a.`name` AS vip_name, a.phone AS vip_phone, a.note AS vip_notes, a.sex AS vip_sex, b.point AS vip_person_point from (select * FROM person   WHERE `name`='%s') a LEFT JOIN point_detail b ON a.id = b.person_id  ORDER BY a.id desc" % (req.GET['username'])
  File "C:\Python27\lib\site-packages\django\utils\datastructures.py", line 85, in __getitem__
    raise MultiValueDictKeyError(repr(key))
MultiValueDictKeyError: "u'username'"
2018-08-09 00:33:24,173 [exception:handle_uncaught_exception] [ERROR]- Internal Server Error: /listVipPerson/
Traceback (most recent call last):
  File "C:\Python27\lib\site-packages\django\core\handlers\exception.py", line 41, in inner
    response = get_response(request)
  File "C:\Python27\lib\site-packages\django\core\handlers\base.py", line 187, in _get_response
    response = self.process_exception_by_middleware(e, request)
  File "C:\Python27\lib\site-packages\django\core\handlers\base.py", line 185, in _get_response
    response = wrapped_callback(request, *callback_args, **callback_kwargs)
  File "D:\Study\VMS\vipMangementSystem\vms\views.py", line 37, in list_vip_person
    limit = int(req.GET['limit'])
  File "C:\Python27\lib\site-packages\django\utils\datastructures.py", line 85, in __getitem__
    raise MultiValueDictKeyError(repr(key))
MultiValueDictKeyError: "u'limit'"
2018-08-09 00:35:29,302 [exception:handle_uncaught_exception] [ERROR]- Internal Server Error: /listVipPerson/
Traceback (most recent call last):
  File "C:\Python27\lib\site-packages\django\core\handlers\exception.py", line 41, in inner
    response = get_response(request)
  File "C:\Python27\lib\site-packages\django\core\handlers\base.py", line 187, in _get_response
    response = self.process_exception_by_middleware(e, request)
  File "C:\Python27\lib\site-packages\django\core\handlers\base.py", line 185, in _get_response
    response = wrapped_callback(request, *callback_args, **callback_kwargs)
  File "D:\Study\VMS\vipMangementSystem\vms\views.py", line 25, in list_vip_person
    sql2 = "SELECT a.id, a.`name` AS vip_name, a.phone AS vip_phone, a.note AS vip_notes, a.sex AS vip_sex, b.point AS vip_person_point from (select * FROM person   WHERE `name`='%s') a LEFT JOIN point_detail b ON a.id = b.person_id  ORDER BY a.id desc" % (req.GET['username'])
  File "C:\Python27\lib\site-packages\django\utils\datastructures.py", line 85, in __getitem__
    raise MultiValueDictKeyError(repr(key))
MultiValueDictKeyError: "u'username'"
2018-08-09 00:36:22,338 [exception:handle_uncaught_exception] [ERROR]- Internal Server Error: /listVipPerson/
Traceback (most recent call last):
  File "C:\Python27\lib\site-packages\django\core\handlers\exception.py", line 41, in inner
    response = get_response(request)
  File "C:\Python27\lib\site-packages\django\core\handlers\base.py", line 187, in _get_response
    response = self.process_exception_by_middleware(e, request)
  File "C:\Python27\lib\site-packages\django\core\handlers\base.py", line 185, in _get_response
    response = wrapped_callback(request, *callback_args, **callback_kwargs)
  File "D:\Study\VMS\vipMangementSystem\vms\views.py", line 22, in list_vip_person
    print(req.GET['username'])
  File "C:\Python27\lib\site-packages\django\utils\datastructures.py", line 85, in __getitem__
    raise MultiValueDictKeyError(repr(key))
MultiValueDictKeyError: "u'username'"
2018-08-09 00:36:28,796 [exception:handle_uncaught_exception] [ERROR]- Internal Server Error: /listVipPerson/
Traceback (most recent call last):
  File "C:\Python27\lib\site-packages\django\core\handlers\exception.py", line 41, in inner
    response = get_response(request)
  File "C:\Python27\lib\site-packages\django\core\handlers\base.py", line 187, in _get_response
    response = self.process_exception_by_middleware(e, request)
  File "C:\Python27\lib\site-packages\django\core\handlers\base.py", line 185, in _get_response
    response = wrapped_callback(request, *callback_args, **callback_kwargs)
  File "D:\Study\VMS\vipMangementSystem\vms\views.py", line 22, in list_vip_person
    print(req.GET['username'])
  File "C:\Python27\lib\site-packages\django\utils\datastructures.py", line 85, in __getitem__
    raise MultiValueDictKeyError(repr(key))
MultiValueDictKeyError: "u'username'"
2018-08-09 00:38:03,690 [exception:handle_uncaught_exception] [ERROR]- Internal Server Error: /listVipPerson/
Traceback (most recent call last):
  File "C:\Python27\lib\site-packages\django\core\handlers\exception.py", line 41, in inner
    response = get_response(request)
  File "C:\Python27\lib\site-packages\django\core\handlers\base.py", line 187, in _get_response
    response = self.process_exception_by_middleware(e, request)
  File "C:\Python27\lib\site-packages\django\core\handlers\base.py", line 185, in _get_response
    response = wrapped_callback(request, *callback_args, **callback_kwargs)
  File "D:\Study\VMS\vipMangementSystem\vms\views.py", line 22, in list_vip_person
    if not req.GET['username'] and not req.GET['sex']:
  File "C:\Python27\lib\site-packages\django\utils\datastructures.py", line 85, in __getitem__
    raise MultiValueDictKeyError(repr(key))
MultiValueDictKeyError: "u'username'"
2018-08-09 00:38:06,717 [exception:handle_uncaught_exception] [ERROR]- Internal Server Error: /listVipPerson/
Traceback (most recent call last):
  File "C:\Python27\lib\site-packages\django\core\handlers\exception.py", line 41, in inner
    response = get_response(request)
  File "C:\Python27\lib\site-packages\django\core\handlers\base.py", line 187, in _get_response
    response = self.process_exception_by_middleware(e, request)
  File "C:\Python27\lib\site-packages\django\core\handlers\base.py", line 185, in _get_response
    response = wrapped_callback(request, *callback_args, **callback_kwargs)
  File "D:\Study\VMS\vipMangementSystem\vms\views.py", line 22, in list_vip_person
    if not req.GET['username'] and not req.GET['sex']:
  File "C:\Python27\lib\site-packages\django\utils\datastructures.py", line 85, in __getitem__
    raise MultiValueDictKeyError(repr(key))
MultiValueDictKeyError: "u'username'"
2018-08-09 00:38:56,098 [exception:handle_uncaught_exception] [ERROR]- Internal Server Error: /listVipPerson/
Traceback (most recent call last):
  File "C:\Python27\lib\site-packages\django\core\handlers\exception.py", line 41, in inner
    response = get_response(request)
  File "C:\Python27\lib\site-packages\django\core\handlers\base.py", line 187, in _get_response
    response = self.process_exception_by_middleware(e, request)
  File "C:\Python27\lib\site-packages\django\core\handlers\base.py", line 185, in _get_response
    response = wrapped_callback(request, *callback_args, **callback_kwargs)
  File "D:\Study\VMS\vipMangementSystem\vms\views.py", line 22, in list_vip_person
    if not req.GET['username'] and not req.GET['sex']:
  File "C:\Python27\lib\site-packages\django\utils\datastructures.py", line 85, in __getitem__
    raise MultiValueDictKeyError(repr(key))
MultiValueDictKeyError: "u'username'"
2018-08-09 00:40:23,463 [exception:handle_uncaught_exception] [ERROR]- Internal Server Error: /listVipPerson/
Traceback (most recent call last):
  File "C:\Python27\lib\site-packages\django\core\handlers\exception.py", line 41, in inner
    response = get_response(request)
  File "C:\Python27\lib\site-packages\django\core\handlers\base.py", line 187, in _get_response
    response = self.process_exception_by_middleware(e, request)
  File "C:\Python27\lib\site-packages\django\core\handlers\base.py", line 185, in _get_response
    response = wrapped_callback(request, *callback_args, **callback_kwargs)
  File "D:\Study\VMS\vipMangementSystem\vms\views.py", line 26, in list_vip_person
    sql= "SELECT a.id, a.`name` AS vip_name, a.phone AS vip_phone, a.note AS vip_notes, a.sex AS vip_sex, b.point AS vip_person_point from (select * FROM person   WHERE `name`='%s') a LEFT JOIN point_detail b ON a.id = b.person_id  ORDER BY a.id desc" % (req.GET['username'])
  File "C:\Python27\lib\site-packages\django\utils\datastructures.py", line 85, in __getitem__
    raise MultiValueDictKeyError(repr(key))
MultiValueDictKeyError: "u'username'"
2018-08-09 00:41:16,641 [exception:handle_uncaught_exception] [ERROR]- Internal Server Error: /listVipPerson/
Traceback (most recent call last):
  File "C:\Python27\lib\site-packages\django\core\handlers\exception.py", line 41, in inner
    response = get_response(request)
  File "C:\Python27\lib\site-packages\django\core\handlers\base.py", line 187, in _get_response
    response = self.process_exception_by_middleware(e, request)
  File "C:\Python27\lib\site-packages\django\core\handlers\base.py", line 185, in _get_response
    response = wrapped_callback(request, *callback_args, **callback_kwargs)
  File "D:\Study\VMS\vipMangementSystem\vms\views.py", line 27, in list_vip_person
    sql= "SELECT a.id, a.`name` AS vip_name, a.phone AS vip_phone, a.note AS vip_notes, a.sex AS vip_sex, b.point AS vip_person_point from (select * FROM person   WHERE `name`='%s') a LEFT JOIN point_detail b ON a.id = b.person_id  ORDER BY a.id desc" % (req.GET['username'])
  File "C:\Python27\lib\site-packages\django\utils\datastructures.py", line 85, in __getitem__
    raise MultiValueDictKeyError(repr(key))
MultiValueDictKeyError: "u'username'"
2018-08-09 00:41:59,572 [exception:handle_uncaught_exception] [ERROR]- Internal Server Error: /listVipPerson/
Traceback (most recent call last):
  File "C:\Python27\lib\site-packages\django\core\handlers\exception.py", line 41, in inner
    response = get_response(request)
  File "C:\Python27\lib\site-packages\django\core\handlers\base.py", line 187, in _get_response
    response = self.process_exception_by_middleware(e, request)
  File "C:\Python27\lib\site-packages\django\core\handlers\base.py", line 185, in _get_response
    response = wrapped_callback(request, *callback_args, **callback_kwargs)
  File "D:\Study\VMS\vipMangementSystem\vms\views.py", line 41, in list_vip_person
    limit = int(req.GET['limit'])
  File "C:\Python27\lib\site-packages\django\utils\datastructures.py", line 85, in __getitem__
    raise MultiValueDictKeyError(repr(key))
MultiValueDictKeyError: "u'limit'"
2018-08-09 00:44:40,789 [exception:handle_uncaught_exception] [ERROR]- Internal Server Error: /listVipPerson/
Traceback (most recent call last):
  File "C:\Python27\lib\site-packages\django\core\handlers\exception.py", line 41, in inner
    response = get_response(request)
  File "C:\Python27\lib\site-packages\django\core\handlers\base.py", line 187, in _get_response
    response = self.process_exception_by_middleware(e, request)
  File "C:\Python27\lib\site-packages\django\core\handlers\base.py", line 185, in _get_response
    response = wrapped_callback(request, *callback_args, **callback_kwargs)
  File "D:\Study\VMS\vipMangementSystem\vms\views.py", line 41, in list_vip_person
    limit = int(req.GET['limit'])
  File "C:\Python27\lib\site-packages\django\utils\datastructures.py", line 85, in __getitem__
    raise MultiValueDictKeyError(repr(key))
MultiValueDictKeyError: "u'limit'"
2018-08-09 21:26:57,969 [base:get_response] [WARNING]- Not Found: /
2018-08-09 21:26:58,098 [base:get_response] [WARNING]- Not Found: /favicon.ico
2018-08-09 21:27:06,976 [exception:handle_uncaught_exception] [ERROR]- Internal Server Error: /listGood/
Traceback (most recent call last):
  File "C:\Python27\lib\site-packages\django\core\handlers\exception.py", line 41, in inner
    response = get_response(request)
  File "C:\Python27\lib\site-packages\django\core\handlers\base.py", line 187, in _get_response
    response = self.process_exception_by_middleware(e, request)
  File "C:\Python27\lib\site-packages\django\core\handlers\base.py", line 185, in _get_response
    response = wrapped_callback(request, *callback_args, **callback_kwargs)
  File "D:\Study\VMS\vipMangementSystem\vms\views.py", line 244, in list_good
    if x['uploadtime'] != '':
KeyError: u'uploadtime'
2018-08-09 21:29:33,181 [base:get_response] [WARNING]- Not Found: /addGood/
2018-08-09 21:30:25,197 [base:get_response] [WARNING]- Not Found: /addGood/
2018-08-09 21:52:23,862 [exception:handle_uncaught_exception] [ERROR]- Internal Server Error: /addGood/
Traceback (most recent call last):
  File "C:\Python27\lib\site-packages\django\core\handlers\exception.py", line 41, in inner
    response = get_response(request)
  File "C:\Python27\lib\site-packages\django\core\handlers\base.py", line 187, in _get_response
    response = self.process_exception_by_middleware(e, request)
  File "C:\Python27\lib\site-packages\django\core\handlers\base.py", line 185, in _get_response
    response = wrapped_callback(request, *callback_args, **callback_kwargs)
  File "D:\Study\VMS\vipMangementSystem\vms\views.py", line 291, in add_good
    sql = "INSERT INTO `good` (`name`, `good_category_id`, `price`, `uploadtime`, `status`) VALUES ('%s', '%s', '%s', now(), '%s');"%(data['title'],data['label'],data['price'],count)
  File "C:\Python27\lib\site-packages\django\utils\datastructures.py", line 85, in __getitem__
    raise MultiValueDictKeyError(repr(key))
MultiValueDictKeyError: "u'label'"
2018-08-09 22:47:31,645 [exception:handle_uncaught_exception] [ERROR]- Internal Server Error: /editGood/
Traceback (most recent call last):
  File "C:\Python27\lib\site-packages\django\core\handlers\exception.py", line 41, in inner
    response = get_response(request)
  File "C:\Python27\lib\site-packages\django\core\handlers\base.py", line 198, in _get_response
    "returned None instead." % (callback.__module__, view_name)
ValueError: The view vms.views.edit_good didn't return an HttpResponse object. It returned None instead.
2018-08-09 23:36:32,736 [exception:handle_uncaught_exception] [ERROR]- Internal Server Error: /editGood/
Traceback (most recent call last):
  File "C:\Python27\lib\site-packages\django\core\handlers\exception.py", line 41, in inner
    response = get_response(request)
  File "C:\Python27\lib\site-packages\django\core\handlers\base.py", line 187, in _get_response
    response = self.process_exception_by_middleware(e, request)
  File "C:\Python27\lib\site-packages\django\core\handlers\base.py", line 185, in _get_response
    response = wrapped_callback(request, *callback_args, **callback_kwargs)
  File "D:\Study\VMS\vipMangementSystem\vms\views.py", line 336, in edit_good
    count = str(int(data['count'])+int(data['add_count']))
UnicodeEncodeError: 'decimal' codec can't encode characters in position 0-7: invalid decimal Unicode string
2018-08-09 23:36:45,838 [exception:handle_uncaught_exception] [ERROR]- Internal Server Error: /editGood/
Traceback (most recent call last):
  File "C:\Python27\lib\site-packages\django\core\handlers\exception.py", line 41, in inner
    response = get_response(request)
  File "C:\Python27\lib\site-packages\django\core\handlers\base.py", line 187, in _get_response
    response = self.process_exception_by_middleware(e, request)
  File "C:\Python27\lib\site-packages\django\core\handlers\base.py", line 185, in _get_response
    response = wrapped_callback(request, *callback_args, **callback_kwargs)
  File "D:\Study\VMS\vipMangementSystem\vms\views.py", line 336, in edit_good
    count = str(int(data['count'])+int(data['add_count']))
ValueError: invalid literal for int() with base 10: 'p'
2018-08-10 23:49:29,845 [base:get_response] [WARNING]- Not Found: /
2018-08-10 23:49:29,966 [base:get_response] [WARNING]- Not Found: /favicon.ico
2018-08-12 16:45:27,003 [base:get_response] [WARNING]- Not Found: /
2018-08-12 16:45:27,130 [base:get_response] [WARNING]- Not Found: /favicon.ico
2018-08-12 16:58:26,670 [exception:handle_uncaught_exception] [ERROR]- Internal Server Error: /listGood/
Traceback (most recent call last):
  File "C:\Python27\lib\site-packages\django\core\handlers\exception.py", line 41, in inner
    response = get_response(request)
  File "C:\Python27\lib\site-packages\django\core\handlers\base.py", line 187, in _get_response
    response = self.process_exception_by_middleware(e, request)
  File "C:\Python27\lib\site-packages\django\core\handlers\base.py", line 185, in _get_response
    response = wrapped_callback(request, *callback_args, **callback_kwargs)
  File "D:\Study\VMS\vipMangementSystem\vms\views.py", line 247, in list_good
    limit = int(req.GET['limit'])
  File "C:\Python27\lib\site-packages\django\utils\datastructures.py", line 85, in __getitem__
    raise MultiValueDictKeyError(repr(key))
MultiValueDictKeyError: "u'limit'"
2018-08-12 16:58:53,790 [exception:handle_uncaught_exception] [ERROR]- Internal Server Error: /listGood/
Traceback (most recent call last):
  File "C:\Python27\lib\site-packages\django\core\handlers\exception.py", line 41, in inner
    response = get_response(request)
  File "C:\Python27\lib\site-packages\django\core\handlers\base.py", line 187, in _get_response
    response = self.process_exception_by_middleware(e, request)
  File "C:\Python27\lib\site-packages\django\core\handlers\base.py", line 185, in _get_response
    response = wrapped_callback(request, *callback_args, **callback_kwargs)
  File "D:\Study\VMS\vipMangementSystem\vms\views.py", line 247, in list_good
    limit = int(req.GET['limit'])
  File "C:\Python27\lib\site-packages\django\utils\datastructures.py", line 85, in __getitem__
    raise MultiValueDictKeyError(repr(key))
MultiValueDictKeyError: "u'limit'"
2018-08-12 16:59:29,092 [exception:handle_uncaught_exception] [ERROR]- Internal Server Error: /listGood/
Traceback (most recent call last):
  File "C:\Python27\lib\site-packages\django\core\handlers\exception.py", line 41, in inner
    response = get_response(request)
  File "C:\Python27\lib\site-packages\django\core\handlers\base.py", line 187, in _get_response
    response = self.process_exception_by_middleware(e, request)
  File "C:\Python27\lib\site-packages\django\core\handlers\base.py", line 185, in _get_response
    response = wrapped_callback(request, *callback_args, **callback_kwargs)
  File "D:\Study\VMS\vipMangementSystem\vms\views.py", line 247, in list_good
    limit = int(req.GET['limit'])
  File "C:\Python27\lib\site-packages\django\utils\datastructures.py", line 85, in __getitem__
    raise MultiValueDictKeyError(repr(key))
MultiValueDictKeyError: "u'limit'"
2018-08-12 16:59:40,184 [exception:handle_uncaught_exception] [ERROR]- Internal Server Error: /listGood/
Traceback (most recent call last):
  File "C:\Python27\lib\site-packages\django\core\handlers\exception.py", line 41, in inner
    response = get_response(request)
  File "C:\Python27\lib\site-packages\django\core\handlers\base.py", line 187, in _get_response
    response = self.process_exception_by_middleware(e, request)
  File "C:\Python27\lib\site-packages\django\core\handlers\base.py", line 185, in _get_response
    response = wrapped_callback(request, *callback_args, **callback_kwargs)
  File "D:\Study\VMS\vipMangementSystem\vms\views.py", line 247, in list_good
    limit = int(req.GET['limit'])
  File "C:\Python27\lib\site-packages\django\utils\datastructures.py", line 85, in __getitem__
    raise MultiValueDictKeyError(repr(key))
MultiValueDictKeyError: "u'limit'"
2018-08-12 17:00:36,624 [exception:handle_uncaught_exception] [ERROR]- Internal Server Error: /listGood/
Traceback (most recent call last):
  File "C:\Python27\lib\site-packages\django\core\handlers\exception.py", line 41, in inner
    response = get_response(request)
  File "C:\Python27\lib\site-packages\django\core\handlers\base.py", line 187, in _get_response
    response = self.process_exception_by_middleware(e, request)
  File "C:\Python27\lib\site-packages\django\core\handlers\base.py", line 185, in _get_response
    response = wrapped_callback(request, *callback_args, **callback_kwargs)
  File "D:\Study\VMS\vipMangementSystem\vms\views.py", line 247, in list_good
    limit = int(req.GET['limit'])
  File "C:\Python27\lib\site-packages\django\utils\datastructures.py", line 85, in __getitem__
    raise MultiValueDictKeyError(repr(key))
MultiValueDictKeyError: "u'limit'"
2018-08-12 17:01:34,118 [exception:handle_uncaught_exception] [ERROR]- Internal Server Error: /listGood/
Traceback (most recent call last):
  File "C:\Python27\lib\site-packages\django\core\handlers\exception.py", line 41, in inner
    response = get_response(request)
  File "C:\Python27\lib\site-packages\django\core\handlers\base.py", line 187, in _get_response
    response = self.process_exception_by_middleware(e, request)
  File "C:\Python27\lib\site-packages\django\core\handlers\base.py", line 185, in _get_response
    response = wrapped_callback(request, *callback_args, **callback_kwargs)
  File "D:\Study\VMS\vipMangementSystem\vms\views.py", line 247, in list_good
    limit = int(req.GET['limit'])
  File "C:\Python27\lib\site-packages\django\utils\datastructures.py", line 85, in __getitem__
    raise MultiValueDictKeyError(repr(key))
MultiValueDictKeyError: "u'limit'"
2018-08-12 17:01:42,404 [exception:handle_uncaught_exception] [ERROR]- Internal Server Error: /listGood/
Traceback (most recent call last):
  File "C:\Python27\lib\site-packages\django\core\handlers\exception.py", line 41, in inner
    response = get_response(request)
  File "C:\Python27\lib\site-packages\django\core\handlers\base.py", line 187, in _get_response
    response = self.process_exception_by_middleware(e, request)
  File "C:\Python27\lib\site-packages\django\core\handlers\base.py", line 185, in _get_response
    response = wrapped_callback(request, *callback_args, **callback_kwargs)
  File "D:\Study\VMS\vipMangementSystem\vms\views.py", line 247, in list_good
    limit = int(req.GET['limit'])
  File "C:\Python27\lib\site-packages\django\utils\datastructures.py", line 85, in __getitem__
    raise MultiValueDictKeyError(repr(key))
MultiValueDictKeyError: "u'limit'"
2018-08-12 17:02:21,111 [exception:handle_uncaught_exception] [ERROR]- Internal Server Error: /listGood/
Traceback (most recent call last):
  File "C:\Python27\lib\site-packages\django\core\handlers\exception.py", line 41, in inner
    response = get_response(request)
  File "C:\Python27\lib\site-packages\django\core\handlers\base.py", line 187, in _get_response
    response = self.process_exception_by_middleware(e, request)
  File "C:\Python27\lib\site-packages\django\core\handlers\base.py", line 185, in _get_response
    response = wrapped_callback(request, *callback_args, **callback_kwargs)
  File "D:\Study\VMS\vipMangementSystem\vms\views.py", line 247, in list_good
    limit = int(req.GET['limit'])
  File "C:\Python27\lib\site-packages\django\utils\datastructures.py", line 85, in __getitem__
    raise MultiValueDictKeyError(repr(key))
MultiValueDictKeyError: "u'limit'"
2018-08-12 17:02:57,351 [exception:handle_uncaught_exception] [ERROR]- Internal Server Error: /listGood/
Traceback (most recent call last):
  File "C:\Python27\lib\site-packages\django\core\handlers\exception.py", line 41, in inner
    response = get_response(request)
  File "C:\Python27\lib\site-packages\django\core\handlers\base.py", line 187, in _get_response
    response = self.process_exception_by_middleware(e, request)
  File "C:\Python27\lib\site-packages\django\core\handlers\base.py", line 185, in _get_response
    response = wrapped_callback(request, *callback_args, **callback_kwargs)
  File "D:\Study\VMS\vipMangementSystem\vms\views.py", line 247, in list_good
    limit = int(req.GET['limit'])
  File "C:\Python27\lib\site-packages\django\utils\datastructures.py", line 85, in __getitem__
    raise MultiValueDictKeyError(repr(key))
MultiValueDictKeyError: "u'limit'"
2018-08-12 17:03:17,686 [exception:handle_uncaught_exception] [ERROR]- Internal Server Error: /listGood/
Traceback (most recent call last):
  File "C:\Python27\lib\site-packages\django\core\handlers\exception.py", line 41, in inner
    response = get_response(request)
  File "C:\Python27\lib\site-packages\django\core\handlers\base.py", line 187, in _get_response
    response = self.process_exception_by_middleware(e, request)
  File "C:\Python27\lib\site-packages\django\core\handlers\base.py", line 185, in _get_response
    response = wrapped_callback(request, *callback_args, **callback_kwargs)
  File "D:\Study\VMS\vipMangementSystem\vms\views.py", line 247, in list_good
    limit = int(req.GET['limit'])
  File "C:\Python27\lib\site-packages\django\utils\datastructures.py", line 85, in __getitem__
    raise MultiValueDictKeyError(repr(key))
MultiValueDictKeyError: "u'limit'"
2018-08-12 17:06:18,766 [exception:handle_uncaught_exception] [ERROR]- Internal Server Error: /listGood/
Traceback (most recent call last):
  File "C:\Python27\lib\site-packages\django\core\handlers\exception.py", line 41, in inner
    response = get_response(request)
  File "C:\Python27\lib\site-packages\django\core\handlers\base.py", line 187, in _get_response
    response = self.process_exception_by_middleware(e, request)
  File "C:\Python27\lib\site-packages\django\core\handlers\base.py", line 185, in _get_response
    response = wrapped_callback(request, *callback_args, **callback_kwargs)
  File "D:\Study\VMS\vipMangementSystem\vms\views.py", line 247, in list_good
    limit = int(req.GET['limit'])
  File "C:\Python27\lib\site-packages\django\utils\datastructures.py", line 85, in __getitem__
    raise MultiValueDictKeyError(repr(key))
MultiValueDictKeyError: "u'limit'"
2018-08-12 17:07:20,187 [exception:handle_uncaught_exception] [ERROR]- Internal Server Error: /listGood/
Traceback (most recent call last):
  File "C:\Python27\lib\site-packages\django\core\handlers\exception.py", line 41, in inner
    response = get_response(request)
  File "C:\Python27\lib\site-packages\django\core\handlers\base.py", line 187, in _get_response
    response = self.process_exception_by_middleware(e, request)
  File "C:\Python27\lib\site-packages\django\core\handlers\base.py", line 185, in _get_response
    response = wrapped_callback(request, *callback_args, **callback_kwargs)
  File "D:\Study\VMS\vipMangementSystem\vms\views.py", line 247, in list_good
    limit = int(req.GET['limit'])
  File "C:\Python27\lib\site-packages\django\utils\datastructures.py", line 85, in __getitem__
    raise MultiValueDictKeyError(repr(key))
MultiValueDictKeyError: "u'limit'"
2018-08-12 17:08:28,558 [exception:handle_uncaught_exception] [ERROR]- Internal Server Error: /listGood/
Traceback (most recent call last):
  File "C:\Python27\lib\site-packages\django\core\handlers\exception.py", line 41, in inner
    response = get_response(request)
  File "C:\Python27\lib\site-packages\django\core\handlers\base.py", line 187, in _get_response
    response = self.process_exception_by_middleware(e, request)
  File "C:\Python27\lib\site-packages\django\core\handlers\base.py", line 185, in _get_response
    response = wrapped_callback(request, *callback_args, **callback_kwargs)
  File "D:\Study\VMS\vipMangementSystem\vms\views.py", line 247, in list_good
    limit = int(req.GET['limit'])
  File "C:\Python27\lib\site-packages\django\utils\datastructures.py", line 85, in __getitem__
    raise MultiValueDictKeyError(repr(key))
MultiValueDictKeyError: "u'limit'"
2018-08-12 21:23:04,355 [base:get_response] [WARNING]- Not Found: /
2018-08-12 21:23:04,483 [base:get_response] [WARNING]- Not Found: /favicon.ico
2018-08-13 22:38:58,956 [base:get_response] [WARNING]- Not Found: /
2018-08-13 22:38:59,138 [base:get_response] [WARNING]- Not Found: /favicon.ico
2018-08-13 23:31:07,706 [exception:handle_uncaught_exception] [ERROR]- Internal Server Error: /addOrder/
Traceback (most recent call last):
  File "C:\Python27\lib\site-packages\django\core\handlers\exception.py", line 41, in inner
    response = get_response(request)
  File "C:\Python27\lib\site-packages\django\core\handlers\base.py", line 187, in _get_response
    response = self.process_exception_by_middleware(e, request)
  File "C:\Python27\lib\site-packages\django\core\handlers\base.py", line 185, in _get_response
    response = wrapped_callback(request, *callback_args, **callback_kwargs)
  File "D:\Study\VMS\vipMangementSystem\vms\views.py", line 590, in add_order
    return HttpResponse(json.dumps(resp), content_type="application/json")
UnboundLocalError: local variable 'resp' referenced before assignment
2018-08-13 23:32:11,661 [exception:handle_uncaught_exception] [ERROR]- Internal Server Error: /addOrder/
Traceback (most recent call last):
  File "C:\Python27\lib\site-packages\django\core\handlers\exception.py", line 41, in inner
    response = get_response(request)
  File "C:\Python27\lib\site-packages\django\core\handlers\base.py", line 187, in _get_response
    response = self.process_exception_by_middleware(e, request)
  File "C:\Python27\lib\site-packages\django\core\handlers\base.py", line 185, in _get_response
    response = wrapped_callback(request, *callback_args, **callback_kwargs)
  File "D:\Study\VMS\vipMangementSystem\vms\views.py", line 591, in add_order
    return HttpResponse(json.dumps(resp), content_type="application/json")
UnboundLocalError: local variable 'resp' referenced before assignment
2018-08-13 23:33:38,058 [exception:handle_uncaught_exception] [ERROR]- Internal Server Error: /addOrder/
Traceback (most recent call last):
  File "C:\Python27\lib\site-packages\django\core\handlers\exception.py", line 41, in inner
    response = get_response(request)
  File "C:\Python27\lib\site-packages\django\core\handlers\base.py", line 187, in _get_response
    response = self.process_exception_by_middleware(e, request)
  File "C:\Python27\lib\site-packages\django\core\handlers\base.py", line 185, in _get_response
    response = wrapped_callback(request, *callback_args, **callback_kwargs)
  File "D:\Study\VMS\vipMangementSystem\vms\views.py", line 591, in add_order
    return HttpResponse(json.dumps(resp), content_type="application/json")
UnboundLocalError: local variable 'resp' referenced before assignment
2018-08-13 23:38:01,845 [exception:handle_uncaught_exception] [ERROR]- Internal Server Error: /addOrder/
Traceback (most recent call last):
  File "C:\Python27\lib\site-packages\django\core\handlers\exception.py", line 41, in inner
    response = get_response(request)
  File "C:\Python27\lib\site-packages\django\core\handlers\base.py", line 187, in _get_response
    response = self.process_exception_by_middleware(e, request)
  File "C:\Python27\lib\site-packages\django\core\handlers\base.py", line 185, in _get_response
    response = wrapped_callback(request, *callback_args, **callback_kwargs)
  File "D:\Study\VMS\vipMangementSystem\vms\views.py", line 588, in add_order
    return HttpResponse(json.dumps(resp), content_type="application/json")
UnboundLocalError: local variable 'resp' referenced before assignment
2018-08-13 23:38:16,459 [exception:handle_uncaught_exception] [ERROR]- Internal Server Error: /addOrder/
Traceback (most recent call last):
  File "C:\Python27\lib\site-packages\django\core\handlers\exception.py", line 41, in inner
    response = get_response(request)
  File "C:\Python27\lib\site-packages\django\core\handlers\base.py", line 187, in _get_response
    response = self.process_exception_by_middleware(e, request)
  File "C:\Python27\lib\site-packages\django\core\handlers\base.py", line 185, in _get_response
    response = wrapped_callback(request, *callback_args, **callback_kwargs)
  File "D:\Study\VMS\vipMangementSystem\vms\views.py", line 588, in add_order
    return HttpResponse(json.dumps(resp), content_type="application/json")
UnboundLocalError: local variable 'resp' referenced before assignment
2018-08-13 23:40:04,184 [exception:handle_uncaught_exception] [ERROR]- Internal Server Error: /addOrder/
Traceback (most recent call last):
  File "C:\Python27\lib\site-packages\django\core\handlers\exception.py", line 41, in inner
    response = get_response(request)
  File "C:\Python27\lib\site-packages\django\core\handlers\base.py", line 187, in _get_response
    response = self.process_exception_by_middleware(e, request)
  File "C:\Python27\lib\site-packages\django\core\handlers\base.py", line 185, in _get_response
    response = wrapped_callback(request, *callback_args, **callback_kwargs)
  File "D:\Study\VMS\vipMangementSystem\vms\views.py", line 573, in add_order
    is_exist = db.getAll('SELECT * from vip_order where `phone` =\'%s\'' % (data['vip_phone']))
  File "C:\Python27\lib\site-packages\django\utils\datastructures.py", line 85, in __getitem__
    raise MultiValueDictKeyError(repr(key))
MultiValueDictKeyError: "u'vip_phone'"
2018-08-13 23:57:20,292 [exception:handle_uncaught_exception] [ERROR]- Internal Server Error: /addOrder/
Traceback (most recent call last):
  File "C:\Python27\lib\site-packages\django\core\handlers\exception.py", line 41, in inner
    response = get_response(request)
  File "C:\Python27\lib\site-packages\django\core\handlers\base.py", line 187, in _get_response
    response = self.process_exception_by_middleware(e, request)
  File "C:\Python27\lib\site-packages\django\core\handlers\base.py", line 185, in _get_response
    response = wrapped_callback(request, *callback_args, **callback_kwargs)
  File "D:\Study\VMS\vipMangementSystem\vms\views.py", line 585, in add_order
    serial_num = time.strftime("%Y%m%d%H%M%S", time.localtime())+str(random.randint(9))
TypeError: randint() takes exactly 3 arguments (2 given)
2018-08-13 23:57:41,431 [exception:handle_uncaught_exception] [ERROR]- Internal Server Error: /addOrder/
Traceback (most recent call last):
  File "C:\Python27\lib\site-packages\django\core\handlers\exception.py", line 41, in inner
    response = get_response(request)
  File "C:\Python27\lib\site-packages\django\core\handlers\base.py", line 187, in _get_response
    response = self.process_exception_by_middleware(e, request)
  File "C:\Python27\lib\site-packages\django\core\handlers\base.py", line 185, in _get_response
    response = wrapped_callback(request, *callback_args, **callback_kwargs)
  File "D:\Study\VMS\vipMangementSystem\vms\views.py", line 585, in add_order
    serial_num = time.strftime("%Y%m%d%H%M%S", time.localtime())+str(random.randint(9))
TypeError: randint() takes exactly 3 arguments (2 given)
2018-08-14 22:57:18,286 [base:get_response] [WARNING]- Not Found: /
2018-08-14 22:57:18,433 [base:get_response] [WARNING]- Not Found: /favicon.ico
2018-08-14 23:28:56,920 [exception:handle_uncaught_exception] [ERROR]- Internal Server Error: /listGood/
Traceback (most recent call last):
  File "C:\Python27\lib\site-packages\django\core\handlers\exception.py", line 41, in inner
    response = get_response(request)
  File "C:\Python27\lib\site-packages\django\core\handlers\base.py", line 187, in _get_response
    response = self.process_exception_by_middleware(e, request)
  File "C:\Python27\lib\site-packages\django\core\handlers\base.py", line 185, in _get_response
    response = wrapped_callback(request, *callback_args, **callback_kwargs)
  File "D:\Study\VMS\vipMangementSystem\vms\views.py", line 275, in list_good
    logger.debug('【商品接口数据】：' + json.dumps(resp))
  File "C:\Python27\lib\json\__init__.py", line 244, in dumps
    return _default_encoder.encode(obj)
  File "C:\Python27\lib\json\encoder.py", line 207, in encode
    chunks = self.iterencode(o, _one_shot=True)
  File "C:\Python27\lib\json\encoder.py", line 270, in iterencode
    return _iterencode(o, 0)
  File "C:\Python27\lib\json\encoder.py", line 184, in default
    raise TypeError(repr(o) + " is not JSON serializable")
TypeError: Decimal('4.00') is not JSON serializable
2018-08-14 23:29:05,243 [exception:handle_uncaught_exception] [ERROR]- Internal Server Error: /listGood/
Traceback (most recent call last):
  File "C:\Python27\lib\site-packages\django\core\handlers\exception.py", line 41, in inner
    response = get_response(request)
  File "C:\Python27\lib\site-packages\django\core\handlers\base.py", line 187, in _get_response
    response = self.process_exception_by_middleware(e, request)
  File "C:\Python27\lib\site-packages\django\core\handlers\base.py", line 185, in _get_response
    response = wrapped_callback(request, *callback_args, **callback_kwargs)
  File "D:\Study\VMS\vipMangementSystem\vms\views.py", line 275, in list_good
    logger.debug('【商品接口数据】：' + json.dumps(resp))
  File "C:\Python27\lib\json\__init__.py", line 244, in dumps
    return _default_encoder.encode(obj)
  File "C:\Python27\lib\json\encoder.py", line 207, in encode
    chunks = self.iterencode(o, _one_shot=True)
  File "C:\Python27\lib\json\encoder.py", line 270, in iterencode
    return _iterencode(o, 0)
  File "C:\Python27\lib\json\encoder.py", line 184, in default
    raise TypeError(repr(o) + " is not JSON serializable")
TypeError: Decimal('4.00') is not JSON serializable
2018-08-14 23:29:08,582 [exception:handle_uncaught_exception] [ERROR]- Internal Server Error: /listGood/
Traceback (most recent call last):
  File "C:\Python27\lib\site-packages\django\core\handlers\exception.py", line 41, in inner
    response = get_response(request)
  File "C:\Python27\lib\site-packages\django\core\handlers\base.py", line 187, in _get_response
    response = self.process_exception_by_middleware(e, request)
  File "C:\Python27\lib\site-packages\django\core\handlers\base.py", line 185, in _get_response
    response = wrapped_callback(request, *callback_args, **callback_kwargs)
  File "D:\Study\VMS\vipMangementSystem\vms\views.py", line 275, in list_good
    logger.debug('【商品接口数据】：' + json.dumps(resp))
  File "C:\Python27\lib\json\__init__.py", line 244, in dumps
    return _default_encoder.encode(obj)
  File "C:\Python27\lib\json\encoder.py", line 207, in encode
    chunks = self.iterencode(o, _one_shot=True)
  File "C:\Python27\lib\json\encoder.py", line 270, in iterencode
    return _iterencode(o, 0)
  File "C:\Python27\lib\json\encoder.py", line 184, in default
    raise TypeError(repr(o) + " is not JSON serializable")
TypeError: Decimal('4.00') is not JSON serializable
2018-08-14 23:29:24,890 [exception:handle_uncaught_exception] [ERROR]- Internal Server Error: /listGood/
Traceback (most recent call last):
  File "C:\Python27\lib\site-packages\django\core\handlers\exception.py", line 41, in inner
    response = get_response(request)
  File "C:\Python27\lib\site-packages\django\core\handlers\base.py", line 187, in _get_response
    response = self.process_exception_by_middleware(e, request)
  File "C:\Python27\lib\site-packages\django\core\handlers\base.py", line 185, in _get_response
    response = wrapped_callback(request, *callback_args, **callback_kwargs)
  File "D:\Study\VMS\vipMangementSystem\vms\views.py", line 275, in list_good
    logger.debug('【商品接口数据】：' + json.dumps(resp))
  File "C:\Python27\lib\json\__init__.py", line 244, in dumps
    return _default_encoder.encode(obj)
  File "C:\Python27\lib\json\encoder.py", line 207, in encode
    chunks = self.iterencode(o, _one_shot=True)
  File "C:\Python27\lib\json\encoder.py", line 270, in iterencode
    return _iterencode(o, 0)
  File "C:\Python27\lib\json\encoder.py", line 184, in default
    raise TypeError(repr(o) + " is not JSON serializable")
TypeError: Decimal('4.00') is not JSON serializable
2018-08-14 23:30:56,114 [exception:handle_uncaught_exception] [ERROR]- Internal Server Error: /listGood/
Traceback (most recent call last):
  File "C:\Python27\lib\site-packages\django\core\handlers\exception.py", line 41, in inner
    response = get_response(request)
  File "C:\Python27\lib\site-packages\django\core\handlers\base.py", line 187, in _get_response
    response = self.process_exception_by_middleware(e, request)
  File "C:\Python27\lib\site-packages\django\core\handlers\base.py", line 185, in _get_response
    response = wrapped_callback(request, *callback_args, **callback_kwargs)
  File "D:\Study\VMS\vipMangementSystem\vms\views.py", line 275, in list_good
    logger.debug('【商品接口数据】：' + json.dumps(resp))
  File "C:\Python27\lib\json\__init__.py", line 244, in dumps
    return _default_encoder.encode(obj)
  File "C:\Python27\lib\json\encoder.py", line 207, in encode
    chunks = self.iterencode(o, _one_shot=True)
  File "C:\Python27\lib\json\encoder.py", line 270, in iterencode
    return _iterencode(o, 0)
  File "C:\Python27\lib\json\encoder.py", line 184, in default
    raise TypeError(repr(o) + " is not JSON serializable")
TypeError: Decimal('4.0') is not JSON serializable
2018-08-14 23:31:52,163 [exception:handle_uncaught_exception] [ERROR]- Internal Server Error: /listGood/
Traceback (most recent call last):
  File "C:\Python27\lib\site-packages\django\core\handlers\exception.py", line 41, in inner
    response = get_response(request)
  File "C:\Python27\lib\site-packages\django\core\handlers\base.py", line 187, in _get_response
    response = self.process_exception_by_middleware(e, request)
  File "C:\Python27\lib\site-packages\django\core\handlers\base.py", line 185, in _get_response
    response = wrapped_callback(request, *callback_args, **callback_kwargs)
  File "D:\Study\VMS\vipMangementSystem\vms\views.py", line 275, in list_good
    logger.debug('【商品接口数据】：' + json.dumps(resp))
  File "C:\Python27\lib\json\__init__.py", line 244, in dumps
    return _default_encoder.encode(obj)
  File "C:\Python27\lib\json\encoder.py", line 207, in encode
    chunks = self.iterencode(o, _one_shot=True)
  File "C:\Python27\lib\json\encoder.py", line 270, in iterencode
    return _iterencode(o, 0)
  File "C:\Python27\lib\json\encoder.py", line 184, in default
    raise TypeError(repr(o) + " is not JSON serializable")
TypeError: Decimal('4.0') is not JSON serializable
2018-08-14 23:34:51,079 [exception:handle_uncaught_exception] [ERROR]- Internal Server Error: /listGood/
Traceback (most recent call last):
  File "C:\Python27\lib\site-packages\django\core\handlers\exception.py", line 41, in inner
    response = get_response(request)
  File "C:\Python27\lib\site-packages\django\core\handlers\base.py", line 187, in _get_response
    response = self.process_exception_by_middleware(e, request)
  File "C:\Python27\lib\site-packages\django\core\handlers\base.py", line 185, in _get_response
    response = wrapped_callback(request, *callback_args, **callback_kwargs)
  File "D:\Study\VMS\vipMangementSystem\vms\views.py", line 276, in list_good
    logger.debug('【商品接口数据】：' + json.dumps(resp))
  File "C:\Python27\lib\json\__init__.py", line 244, in dumps
    return _default_encoder.encode(obj)
  File "C:\Python27\lib\json\encoder.py", line 207, in encode
    chunks = self.iterencode(o, _one_shot=True)
  File "C:\Python27\lib\json\encoder.py", line 270, in iterencode
    return _iterencode(o, 0)
  File "C:\Python27\lib\json\encoder.py", line 184, in default
    raise TypeError(repr(o) + " is not JSON serializable")
TypeError: Decimal('4.0') is not JSON serializable
2018-08-14 23:58:53,805 [exception:handle_uncaught_exception] [ERROR]- Internal Server Error: /addGood/
Traceback (most recent call last):
  File "C:\Python27\lib\site-packages\django\core\handlers\exception.py", line 41, in inner
    response = get_response(request)
  File "C:\Python27\lib\site-packages\django\core\handlers\base.py", line 187, in _get_response
    response = self.process_exception_by_middleware(e, request)
  File "C:\Python27\lib\site-packages\django\core\handlers\base.py", line 185, in _get_response
    response = wrapped_callback(request, *callback_args, **callback_kwargs)
  File "D:\Study\VMS\vipMangementSystem\vms\views.py", line 289, in add_good
    print (float(data['origin_price']))
  File "C:\Python27\lib\site-packages\django\utils\datastructures.py", line 85, in __getitem__
    raise MultiValueDictKeyError(repr(key))
MultiValueDictKeyError: "u'origin_price'"
2018-08-14 23:59:38,003 [exception:handle_uncaught_exception] [ERROR]- Internal Server Error: /addGood/
Traceback (most recent call last):
  File "C:\Python27\lib\site-packages\django\core\handlers\exception.py", line 41, in inner
    response = get_response(request)
  File "C:\Python27\lib\site-packages\django\core\handlers\base.py", line 187, in _get_response
    response = self.process_exception_by_middleware(e, request)
  File "C:\Python27\lib\site-packages\django\core\handlers\base.py", line 185, in _get_response
    response = wrapped_callback(request, *callback_args, **callback_kwargs)
  File "D:\Study\VMS\vipMangementSystem\vms\views.py", line 302, in add_good
    sql = "INSERT INTO `good` (`name`, `good_category_id`, `price`, `uploadtime`, `status`,`origin_price`) VALUES ('%s', '%s', '%s', now(), '%s','%s');"%(data['title'],data['type'],data['price'],count,data['origin_price'])
  File "C:\Python27\lib\site-packages\django\utils\datastructures.py", line 85, in __getitem__
    raise MultiValueDictKeyError(repr(key))
MultiValueDictKeyError: "u'origin_price'"
2018-08-15 00:36:52,966 [exception:handle_uncaught_exception] [ERROR]- Internal Server Error: /addOrder/
Traceback (most recent call last):
  File "C:\Python27\lib\site-packages\django\core\handlers\exception.py", line 41, in inner
    response = get_response(request)
  File "C:\Python27\lib\site-packages\django\core\handlers\base.py", line 187, in _get_response
    response = self.process_exception_by_middleware(e, request)
  File "C:\Python27\lib\site-packages\django\core\handlers\base.py", line 185, in _get_response
    response = wrapped_callback(request, *callback_args, **callback_kwargs)
  File "D:\Study\VMS\vipMangementSystem\vms\views.py", line 650, in add_order
    good_list.append(x.split('=')[1])
IndexError: list index out of range
2018-08-15 00:38:54,019 [exception:handle_uncaught_exception] [ERROR]- Internal Server Error: /addOrder/
Traceback (most recent call last):
  File "C:\Python27\lib\site-packages\django\core\handlers\exception.py", line 41, in inner
    response = get_response(request)
  File "C:\Python27\lib\site-packages\django\core\handlers\base.py", line 187, in _get_response
    response = self.process_exception_by_middleware(e, request)
  File "C:\Python27\lib\site-packages\django\core\handlers\base.py", line 185, in _get_response
    response = wrapped_callback(request, *callback_args, **callback_kwargs)
  File "D:\Study\VMS\vipMangementSystem\vms\views.py", line 650, in add_order
    good_list.append(x.split('=')[1])
IndexError: list index out of range
2018-08-15 00:52:10,622 [exception:handle_uncaught_exception] [ERROR]- Internal Server Error: /addOrder/
Traceback (most recent call last):
  File "C:\Python27\lib\site-packages\django\core\handlers\exception.py", line 41, in inner
    response = get_response(request)
  File "C:\Python27\lib\site-packages\django\core\handlers\base.py", line 187, in _get_response
    response = self.process_exception_by_middleware(e, request)
  File "C:\Python27\lib\site-packages\django\core\handlers\base.py", line 185, in _get_response
    response = wrapped_callback(request, *callback_args, **callback_kwargs)
  File "D:\Study\VMS\vipMangementSystem\vms\views.py", line 656, in add_order
    dd2 = db.insertMany(sql2)
  File "D:\Study\VMS\vipMangementSystem\vms\DB.py", line 188, in insertMany
    count = self._cursor.executemany(sql)
  File "C:\Python27\lib\site-packages\DBUtils\SteadyDB.py", line 580, in tough_method
    result = method(*args, **kwargs)  # try to execute
TypeError: executemany() takes exactly 3 arguments (2 given)
2018-08-15 00:53:42,865 [exception:handle_uncaught_exception] [ERROR]- Internal Server Error: /addOrder/
Traceback (most recent call last):
  File "C:\Python27\lib\site-packages\django\core\handlers\exception.py", line 41, in inner
    response = get_response(request)
  File "C:\Python27\lib\site-packages\django\core\handlers\base.py", line 187, in _get_response
    response = self.process_exception_by_middleware(e, request)
  File "C:\Python27\lib\site-packages\django\core\handlers\base.py", line 185, in _get_response
    response = wrapped_callback(request, *callback_args, **callback_kwargs)
  File "D:\Study\VMS\vipMangementSystem\vms\views.py", line 657, in add_order
    dd2 = db.insertMany(sql2)
  File "D:\Study\VMS\vipMangementSystem\vms\DB.py", line 188, in insertMany
    count = self._cursor.executemany(sql)
  File "C:\Python27\lib\site-packages\DBUtils\SteadyDB.py", line 580, in tough_method
    result = method(*args, **kwargs)  # try to execute
TypeError: executemany() takes exactly 3 arguments (2 given)
2018-08-15 00:55:20,217 [exception:handle_uncaught_exception] [ERROR]- Internal Server Error: /addOrder/
Traceback (most recent call last):
  File "C:\Python27\lib\site-packages\django\core\handlers\exception.py", line 41, in inner
    response = get_response(request)
  File "C:\Python27\lib\site-packages\django\core\handlers\base.py", line 187, in _get_response
    response = self.process_exception_by_middleware(e, request)
  File "C:\Python27\lib\site-packages\django\core\handlers\base.py", line 185, in _get_response
    response = wrapped_callback(request, *callback_args, **callback_kwargs)
  File "D:\Study\VMS\vipMangementSystem\vms\views.py", line 657, in add_order
    dd2 = db.insertMany(sql2)
  File "D:\Study\VMS\vipMangementSystem\vms\DB.py", line 188, in insertMany
    count = self._cursor.executemany(sql)
  File "C:\Python27\lib\site-packages\DBUtils\SteadyDB.py", line 580, in tough_method
    result = method(*args, **kwargs)  # try to execute
TypeError: executemany() takes exactly 3 arguments (2 given)
2018-08-15 00:56:25,851 [exception:handle_uncaught_exception] [ERROR]- Internal Server Error: /addOrder/
Traceback (most recent call last):
  File "C:\Python27\lib\site-packages\django\core\handlers\exception.py", line 41, in inner
    response = get_response(request)
  File "C:\Python27\lib\site-packages\django\core\handlers\base.py", line 187, in _get_response
    response = self.process_exception_by_middleware(e, request)
  File "C:\Python27\lib\site-packages\django\core\handlers\base.py", line 185, in _get_response
    response = wrapped_callback(request, *callback_args, **callback_kwargs)
  File "D:\Study\VMS\vipMangementSystem\vms\views.py", line 657, in add_order
    dd2 = db.insertMany(sql2)
  File "D:\Study\VMS\vipMangementSystem\vms\DB.py", line 188, in insertMany
    count = self._cursor.executemany(sql)
  File "C:\Python27\lib\site-packages\DBUtils\SteadyDB.py", line 580, in tough_method
    result = method(*args, **kwargs)  # try to execute
TypeError: executemany() takes exactly 3 arguments (2 given)
